Workbook

Sheet README
A1: Pipeline Office Systems - monthly close workbook - 2026-02
A2: Status: Closed and validated by the CFO
A4: Steps (as done by Claire Donnelly, Financial Controller):
A5: 1. Export GL detail for the month from the ERP (P&L accounts 4000-6999).
A6: 2. Paste the export into GL_import (replace last month's rows).
A7: 3. Check Mapping: no account may show UNMAPPED in GL_import column M.
A8: 4. Check total: sum of net in GL_import equals the ERP P&L total.
A9: 5. Review PnL_vs_Budget; every line with |variance| >= 5,000 EUR needs a comment.
A10: 6. Write the explanations in Commentary, with the source of each explanation.
A11: 7. Update the management pack slides and send to the CFO.
A13: Sign convention: variance > 0 is favourable, < 0 is adverse.
A14: Fictional data for the 42 Paris x screenpipe hackathon.

Sheet GL_import
A1: entry_id | B1: posting_date | C1: period | D1: journal | E1: account | F1: account_name | G1: cost_centre | H1: counterparty | I1: document_ref | J1: description | K1: debit | L1: credit | M1: line_code | N1: net
A2: JE-202602-0001 | B2: 2026-02-02 | C2: 2026-02 | D2: SAL | E2: 4010 | F2: Sales - dealers | G2: SALES | H2: DeskWorks Dealers | I2: SI-2602495 | J2: Dealer order | K2: 0 | L2: 69773.04 | M2: =IFERROR(VLOOKUP(E2,Mapping!$A:$B,2,FALSE),"UNMAPPED") | N2: =L2-K2
A3: JE-202602-0002 | B3: 2026-02-02 | C3: 2026-02 | D3: PUR | E3: 6200 | F3: Rent and service charges | G3: ADMIN | I3: PI-26022182 | J3: Rent and service charge | K3: 40000 | L3: 0 | M3: =IFERROR(VLOOKUP(E3,Mapping!$A:$B,2,FALSE),"UNMAPPED") | N3: =L3-K3
A4: JE-202602-0003 | B4: 2026-02-03 | C4: 2026-02 | D4: SAL | E4: 4000 | F4: Sales - contract customers | G4: SALES | H4: Belvedere Hotel Group | I4: SI-2602430 | J4: Contract delivery | K4: 0 | L4: 97490.19 | M4: =IFERROR(VLOOKUP(E4,Mapping!$A:$B,2,FALSE),"UNMAPPED") | N4: =L4-K4
A5: JE-202602-0004 | B5: 2026-02-03 | C5: 2026-02 | D5: PUR | E5: 5010 | F5: Purchases - metal fittings | G5: PROD | H5: Halvorsen Fittings | I5: PI-26028250 | J5: Hinges, frames and fittings | K5: 22449.47 | L5: 0 | M5: =IFERROR(VLOOKUP(E5,Mapping!$A:$B,2,FALSE),"UNMAPPED") | N5: =L5-K5
A6: JE-202602-0005 | B6: 2026-02-04 | C6: 2026-02 | D6: SAL | E6: 4000 | F6: Sales - contract customers | G6: SALES | H6: Harbour City Council | I6: SI-2602309 | J6: Contract delivery | K6: 0 | L6: 104140.45 | M6: =IFERROR(VLOOKUP(E6,Mapping!$A:$B,2,FALSE),"UNMAPPED") | N6: =L6-K6
A7: JE-202602-0006 | B7: 2026-02-04 | C7: 2026-02 | D7: PUR | E7: 5200 | F7: Carriage outwards | G7: LOG | H7: Atlantic Freight Services | I7: PI-26026174 | J7: Standard road freight | K7: 11407.75 | L7: 0 | M7: =IFERROR(VLOOKUP(E7,Mapping!$A:$B,2,FALSE),"UNMAPPED") | N7: =L7-K7
A8: JE-202602-0007 | B8: 2026-02-04 | C8: 2026-02 | D8: PUR | E8: 6300 | F8: Other overheads | G8: ADMIN | I8: PI-26029573 | J8: Overheads | K8: 9717.72 | L8: 0 | M8: =IFERROR(VLOOKUP(E8,Mapping!$A:$B,2,FALSE),"UNMAPPED") | N8: =L8-K8
A9: JE-202602-0008 | B9: 2026-02-05 | C9: 2026-02 | D9: SAL | E9: 4010 | F9: Sales - dealers | G9: SALES | H9: OfficeLine Distribution | I9: SI-2602814 | J9: Dealer order | K9: 0 | L9: 57338.27 | M9: =IFERROR(VLOOKUP(E9,Mapping!$A:$B,2,FALSE),"UNMAPPED") | N9: =L9-K9
A10: JE-202602-0009 | B10: 2026-02-05 | C10: 2026-02 | D10: PUR | E10: 5000 | F10: Purchases - timber and panels | G10: PROD | H10: Oakfield Panels | I10: PI-26021540 | J10: Panels and boards | K10: 19105.23 | L10: 0 | M10: =IFERROR(VLOOKUP(E10,Mapping!$A:$B,2,FALSE),"UNMAPPED") | N10: =L10-K10
A11: JE-202602-0010 | B11: 2026-02-05 | C11: 2026-02 | D11: PUR | E11: 5000 | F11: Purchases - timber and panels | G11: PROD | H11: Nordboard Supplies | I11: PI-26022313 | J11: Panels and boards | K11: 32010.85 | L11: 0 | M11: =IFERROR(VLOOKUP(E11,Mapping!$A:$B,2,FALSE),"UNMAPPED") | N11: =L11-K11
A12: JE-202602-0011 | B12: 2026-02-05 | C12: 2026-02 | D12: PUR | E12: 6300 | F12: Other overheads | G12: ADMIN | I12: PI-26023449 | J12: Overheads | K12: 5571.87 | L12: 0 | M12: =IFERROR(VLOOKUP(E12,Mapping!$A:$B,2,FALSE),"UNMAPPED") | N12: =L12-K12
A13: JE-202602-0012 | B13: 2026-02-06 | C13: 2026-02 | D13: PUR | E13: 5000 | F13: Purchases - timber and panels | G13: PROD | H13: Brightwood Timber Ltd | I13: BW-INV-10588 | J13: Oak and birch veneer panels - price list 2026-02 | K13: 52200 | L13: 0 | M13: =IFERROR(VLOOKUP(E13,Mapping!$A:$B,2,FALSE),"UNMAPPED") | N13: =L13-K13
A14: JE-202602-0013 | B14: 2026-02-06 | C14: 2026-02 | D14: PUR | E14: 6100 | F14: Audit, legal and consulting fees | G14: ADMIN | H14: Harrowgate Audit & Tax | I14: PI-26022699 | J14: Monthly retainer | K14: 9606.04 | L14: 0 | M14: =IFERROR(VLOOKUP(E14,Mapping!$A:$B,2,FALSE),"UNMAPPED") | N14: =L14-K14
A15: JE-202602-0014 | B15: 2026-02-09 | C15: 2026-02 | D15: PUR | E15: 6000 | F15: Electricity and gas | G15: ADMIN | H15: Celtic Energy Supply | I15: PI-26029627 | J15: Monthly energy invoice | K15: 31900 | L15: 0 | M15: =IFERROR(VLOOKUP(E15,Mapping!$A:$B,2,FALSE),"UNMAPPED") | N15: =L15-K15
A16: JE-202602-0015 | B16: 2026-02-10 | C16: 2026-02 | D16: SAL | E16: 4000 | F16: Sales - contract customers | G16: SALES | H16: Quayside Co-working | I16: SI-2602434 | J16: Contract delivery | K16: 0 | L16: 111876.51 | M16: =IFERROR(VLOOKUP(E16,Mapping!$A:$B,2,FALSE),"UNMAPPED") | N16: =L16-K16
A17: JE-202602-0016 | B17: 2026-02-10 | C17: 2026-02 | D17: PUR | E17: 5200 | F17: Carriage outwards | G17: LOG | H17: Atlantic Freight Services | I17: PI-26028225 | J17: Standard road freight | K17: 10878.25 | L17: 0 | M17: =IFERROR(VLOOKUP(E17,Mapping!$A:$B,2,FALSE),"UNMAPPED") | N17: =L17-K17
A18: JE-202602-0017 | B18: 2026-02-10 | C18: 2026-02 | D18: PUR | E18: 6300 | F18: Other overheads | G18: ADMIN | I18: PI-26027408 | J18: Overheads | K18: 9065.64 | L18: 0 | M18: =IFERROR(VLOOKUP(E18,Mapping!$A:$B,2,FALSE),"UNMAPPED") | N18: =L18-K18
A19: JE-202602-0018 | B19: 2026-02-11 | C19: 2026-02 | D19: PUR | E19: 5010 | F19: Purchases - metal fittings | G19: PROD | H19: Halvorsen Fittings | I19: PI-26023718 | J19: Hinges, frames and fittings | K19: 37957.77 | L19: 0 | M19: =IFERROR(VLOOKUP(E19,Mapping!$A:$B,2,FALSE),"UNMAPPED") | N19: =L19-K19
A20: JE-202602-0019 | B20: 2026-02-12 | C20: 2026-02 | D20: SAL | E20: 4000 | F20: Sales - contract customers | G20: SALES | H20: Meridian Insurance | I20: SI-2602147 | J20: Contract delivery | K20: 0 | L20: 61980.69 | M20: =IFERROR(VLOOKUP(E20,Mapping!$A:$B,2,FALSE),"UNMAPPED") | N20: =L20-K20
A21: JE-202602-0020 | B21: 2026-02-12 | C21: 2026-02 | D21: SAL | E21: 4010 | F21: Sales - dealers | G21: SALES | H21: Workspace Hub Retail | I21: SI-2602965 | J21: Dealer order | K21: 0 | L21: 92570.16 | M21: =IFERROR(VLOOKUP(E21,Mapping!$A:$B,2,FALSE),"UNMAPPED") | N21: =L21-K21
A22: JE-202602-0021 | B22: 2026-02-12 | C22: 2026-02 | D22: PUR | E22: 5000 | F22: Purchases - timber and panels | G22: PROD | H22: Oakfield Panels | I22: PI-26025757 | J22: Panels and boards | K22: 17614.58 | L22: 0 | M22: =IFERROR(VLOOKUP(E22,Mapping!$A:$B,2,FALSE),"UNMAPPED") | N22: =L22-K22
A23: JE-202602-0022 | B23: 2026-02-13 | C23: 2026-02 | D23: SAL | E23: 4000 | F23: Sales - contract customers | G23: SALES | H23: Lough Valley University | I23: SI-2602535 | J23: Contract delivery | K23: 0 | L23: 104808.44 | M23: =IFERROR(VLOOKUP(E23,Mapping!$A:$B,2,FALSE),"UNMAPPED") | N23: =L23-K23
A24: JE-202602-0023 | B24: 2026-02-13 | C24: 2026-02 | D24: PUR | E24: 6300 | F24: Other overheads | G24: ADMIN | I24: PI-26022700 | J24: Overheads | K24: 8571.4 | L24: 0 | M24: =IFERROR(VLOOKUP(E24,Mapping!$A:$B,2,FALSE),"UNMAPPED") | N24: =L24-K24
A25: JE-202602-0024 | B25: 2026-02-16 | C25: 2026-02 | D25: SAL | E25: 4010 | F25: Sales - dealers | G25: SALES | H25: DeskWorks Dealers | I25: SI-2602499 | J25: Dealer order | K25: 0 | L25: 62865.32 | M25: =IFERROR(VLOOKUP(E25,Mapping!$A:$B,2,FALSE),"UNMAPPED") | N25: =L25-K25
A26: JE-202602-0025 | B26: 2026-02-16 | C26: 2026-02 | D26: PUR | E26: 5000 | F26: Purchases - timber and panels | G26: PROD | H26: Brightwood Timber Ltd | I26: BW-INV-10631 | J26: Oak and birch veneer panels - price list 2026-02 | K26: 52200 | L26: 0 | M26: =IFERROR(VLOOKUP(E26,Mapping!$A:$B,2,FALSE),"UNMAPPED") | N26: =L26-K26
A27: JE-202602-0026 | B27: 2026-02-16 | C27: 2026-02 | D27: PUR | E27: 5010 | F27: Purchases - metal fittings | G27: PROD | H27: Halvorsen Fittings | I27: PI-26025973 | J27: Hinges, frames and fittings | K27: 32867.25 | L27: 0 | M27: =IFERROR(VLOOKUP(E27,Mapping!$A:$B,2,FALSE),"UNMAPPED") | N27: =L27-K27
A28: JE-202602-0027 | B28: 2026-02-16 | C28: 2026-02 | D28: PUR | E28: 5200 | F28: Carriage outwards | G28: LOG | H28: Atlantic Freight Services | I28: PI-26023486 | J28: Standard road freight | K28: 11009.86 | L28: 0 | M28: =IFERROR(VLOOKUP(E28,Mapping!$A:$B,2,FALSE),"UNMAPPED") | N28: =L28-K28
A29: JE-202602-0028 | B29: 2026-02-16 | C29: 2026-02 | D29: PUR | E29: 6300 | F29: Other overheads | G29: ADMIN | I29: PI-26022502 | J29: Overheads | K29: 8938.65 | L29: 0 | M29: =IFERROR(VLOOKUP(E29,Mapping!$A:$B,2,FALSE),"UNMAPPED") | N29: =L29-K29
A30: JE-202602-0029 | B30: 2026-02-18 | C30: 2026-02 | D30: SAL | E30: 4010 | F30: Sales - dealers | G30: SALES | H30: OfficeLine Distribution | I30: SI-2602416 | J30: Dealer order | K30: 0 | L30: 57484.91 | M30: =IFERROR(VLOOKUP(E30,Mapping!$A:$B,2,FALSE),"UNMAPPED") | N30: =L30-K30
A31: JE-202602-0030 | B31: 2026-02-18 | C31: 2026-02 | D31: PUR | E31: 5000 | F31: Purchases - timber and panels | G31: PROD | H31: Nordboard Supplies | I31: PI-26023836 | J31: Panels and boards | K31: 19417.28 | L31: 0 | M31: =IFERROR(VLOOKUP(E31,Mapping!$A:$B,2,FALSE),"UNMAPPED") | N31: =L31-K31
A32: JE-202602-0031 | B32: 2026-02-19 | C32: 2026-02 | D32: SAL | E32: 4000 | F32: Sales - contract customers | G32: SALES | H32: Belvedere Hotel Group | I32: SI-2602364 | J32: Contract delivery | K32: 0 | L32: 95720.3 | M32: =IFERROR(VLOOKUP(E32,Mapping!$A:$B,2,FALSE),"UNMAPPED") | N32: =L32-K32
A33: JE-202602-0032 | B33: 2026-02-19 | C33: 2026-02 | D33: PUR | E33: 5000 | F33: Purchases - timber and panels | G33: PROD | H33: Oakfield Panels | I33: PI-26027421 | J33: Panels and boards | K33: 31337.78 | L33: 0 | M33: =IFERROR(VLOOKUP(E33,Mapping!$A:$B,2,FALSE),"UNMAPPED") | N33: =L33-K33
A34: JE-202602-0033 | B34: 2026-02-19 | C34: 2026-02 | D34: PUR | E34: 6300 | F34: Other overheads | G34: ADMIN | I34: PI-26021853 | J34: Overheads | K34: 6114.12 | L34: 0 | M34: =IFERROR(VLOOKUP(E34,Mapping!$A:$B,2,FALSE),"UNMAPPED") | N34: =L34-K34
A35: JE-202602-0034 | B35: 2026-02-20 | C35: 2026-02 | D35: SAL | E35: 4000 | F35: Sales - contract customers | G35: SALES | H35: Harbour City Council | I35: SI-2602243 | J35: Contract delivery | K35: 0 | L35: 57465.01 | M35: =IFERROR(VLOOKUP(E35,Mapping!$A:$B,2,FALSE),"UNMAPPED") | N35: =L35-K35
A36: JE-202602-0035 | B36: 2026-02-23 | C36: 2026-02 | D36: PUR | E36: 5010 | F36: Purchases - metal fittings | G36: PROD | H36: Halvorsen Fittings | I36: PI-26027181 | J36: Hinges, frames and fittings | K36: 22625.51 | L36: 0 | M36: =IFERROR(VLOOKUP(E36,Mapping!$A:$B,2,FALSE),"UNMAPPED") | N36: =L36-K36
A37: JE-202602-0036 | B37: 2026-02-23 | C37: 2026-02 | D37: PUR | E37: 6300 | F37: Other overheads | G37: ADMIN | I37: PI-26029384 | J37: Overheads | K37: 5089.3 | L37: 0 | M37: =IFERROR(VLOOKUP(E37,Mapping!$A:$B,2,FALSE),"UNMAPPED") | N37: =L37-K37
A38: JE-202602-0037 | B38: 2026-02-24 | C38: 2026-02 | D38: SAL | E38: 4000 | F38: Sales - contract customers | G38: SALES | H38: Quayside Co-working | I38: SI-2602836 | J38: Contract delivery | K38: 0 | L38: 87206.47 | M38: =IFERROR(VLOOKUP(E38,Mapping!$A:$B,2,FALSE),"UNMAPPED") | N38: =L38-K38
A39: JE-202602-0038 | B39: 2026-02-24 | C39: 2026-02 | D39: PUR | E39: 5200 | F39: Carriage outwards | G39: LOG | H39: Atlantic Freight Services | I39: PI-26021659 | J39: Standard road freight | K39: 11304.14 | L39: 0 | M39: =IFERROR(VLOOKUP(E39,Mapping!$A:$B,2,FALSE),"UNMAPPED") | N39: =L39-K39
A40: JE-202602-0039 | B40: 2026-02-24 | C40: 2026-02 | D40: PUR | E40: 6100 | F40: Audit, legal and consulting fees | G40: ADMIN | H40: Quay Legal LLP | I40: PI-26024930 | J40: Monthly retainer | K40: 5393.96 | L40: 0 | M40: =IFERROR(VLOOKUP(E40,Mapping!$A:$B,2,FALSE),"UNMAPPED") | N40: =L40-K40
...

Sheet Mapping
A1: account | B1: line_code | C1: line_name
A2: 4000 | B2: REV_CONTRACT | C2: Revenue - Contract
A3: 4010 | B3: REV_DEALER | C3: Revenue - Dealers
A4: 5000 | B4: MAT_TIMBER | C4: Timber & panels
A5: 5010 | B5: MAT_FITTINGS | C5: Metal fittings & hardware
A6: 5100 | B6: LAB_DIRECT | C6: Direct labour
A7: 5110 | B7: LAB_TEMP | C7: Temporary labour
A8: 5200 | B8: FREIGHT | C8: Freight out
A9: 6000 | B9: ENERGY | C9: Energy
A10: 6100 | B10: FEES | C10: Professional fees
A11: 6200 | B11: RENT | C11: Rent & facilities
A12: 6300 | B12: OTHER | C12: Other overheads
A13: 6400 | B13: LAB_ADMIN | C13: Salaries - admin & sales

Sheet PnL_vs_Budget
A1: line_code | B1: line_name | C1: sign | D1: actual | E1: budget | F1: variance (fav +) | G1: variance % | H1: comment needed
A2: REV_CONTRACT | B2: Revenue - Contract | C2: 1 | D2: =SUMIFS(GL_import!$N$2:$N$51,GL_import!$M$2:$M$51,A2)*C2 | E2: 820000 | F2: =(D2-E2)*C2 | G2: =IF(E2=0,"",F2/E2) | H2: =IF(ABS(F2)>=5000,"YES","")
A3: REV_DEALER | B3: Revenue - Dealers | C3: 1 | D3: =SUMIFS(GL_import!$N$2:$N$51,GL_import!$M$2:$M$51,A3)*C3 | E3: 480000 | F3: =(D3-E3)*C3 | G3: =IF(E3=0,"",F3/E3) | H3: =IF(ABS(F3)>=5000,"YES","")
A4: REV_ONLINE | B4: Revenue - Online | C4: 1 | D4: =SUMIFS(GL_import!$N$2:$N$51,GL_import!$M$2:$M$51,A4)*C4 | E4: 0 | F4: =(D4-E4)*C4 | G4: =IF(E4=0,"",F4/E4) | H4: =IF(ABS(F4)>=5000,"YES","")
A5: MAT_TIMBER | B5: Timber & panels | C5: -1 | D5: =SUMIFS(GL_import!$N$2:$N$51,GL_import!$M$2:$M$51,A5)*C5 | E5: 290000 | F5: =(D5-E5)*C5 | G5: =IF(E5=0,"",F5/E5) | H5: =IF(ABS(F5)>=5000,"YES","")
A6: MAT_FITTINGS | B6: Metal fittings & hardware | C6: -1 | D6: =SUMIFS(GL_import!$N$2:$N$51,GL_import!$M$2:$M$51,A6)*C6 | E6: 115000 | F6: =(D6-E6)*C6 | G6: =IF(E6=0,"",F6/E6) | H6: =IF(ABS(F6)>=5000,"YES","")
A7: LAB_DIRECT | B7: Direct labour | C7: -1 | D7: =SUMIFS(GL_import!$N$2:$N$51,GL_import!$M$2:$M$51,A7)*C7 | E7: 255000 | F7: =(D7-E7)*C7 | G7: =IF(E7=0,"",F7/E7) | H7: =IF(ABS(F7)>=5000,"YES","")
A8: LAB_TEMP | B8: Temporary labour | C8: -1 | D8: =SUMIFS(GL_import!$N$2:$N$51,GL_import!$M$2:$M$51,A8)*C8 | E8: 8000 | F8: =(D8-E8)*C8 | G8: =IF(E8=0,"",F8/E8) | H8: =IF(ABS(F8)>=5000,"YES","")
A9: FREIGHT | B9: Freight out | C9: -1 | D9: =SUMIFS(GL_import!$N$2:$N$51,GL_import!$M$2:$M$51,A9)*C9 | E9: 44000 | F9: =(D9-E9)*C9 | G9: =IF(E9=0,"",F9/E9) | H9: =IF(ABS(F9)>=5000,"YES","")
A10: ENERGY | B10: Energy | C10: -1 | D10: =SUMIFS(GL_import!$N$2:$N$51,GL_import!$M$2:$M$51,A10)*C10 | E10: 31000 | F10: =(D10-E10)*C10 | G10: =IF(E10=0,"",F10/E10) | H10: =IF(ABS(F10)>=5000,"YES","")
A11: FEES | B11: Professional fees | C11: -1 | D11: =SUMIFS(GL_import!$N$2:$N$51,GL_import!$M$2:$M$51,A11)*C11 | E11: 15000 | F11: =(D11-E11)*C11 | G11: =IF(E11=0,"",F11/E11) | H11: =IF(ABS(F11)>=5000,"YES","")
A12: RENT | B12: Rent & facilities | C12: -1 | D12: =SUMIFS(GL_import!$N$2:$N$51,GL_import!$M$2:$M$51,A12)*C12 | E12: 40000 | F12: =(D12-E12)*C12 | G12: =IF(E12=0,"",F12/E12) | H12: =IF(ABS(F12)>=5000,"YES","")
A13: OTHER | B13: Other overheads | C13: -1 | D13: =SUMIFS(GL_import!$N$2:$N$51,GL_import!$M$2:$M$51,A13)*C13 | E13: 58000 | F13: =(D13-E13)*C13 | G13: =IF(E13=0,"",F13/E13) | H13: =IF(ABS(F13)>=5000,"YES","")
A14: LAB_ADMIN | B14: Salaries - admin & sales | C14: -1 | D14: =SUMIFS(GL_import!$N$2:$N$51,GL_import!$M$2:$M$51,A14)*C14 | E14: 120000 | F14: =(D14-E14)*C14 | G14: =IF(E14=0,"",F14/E14) | H14: =IF(ABS(F14)>=5000,"YES","")
A15: UNMAPPED | B15: Accounts missing from Mapping | C15: 1 | D15: =SUMIFS(GL_import!$N$2:$N$51,GL_import!$M$2:$M$51,"UNMAPPED") | E15: 0 | F15: =D15 | H15: =IF(D15<>0,"FIX MAPPING","")
A16: EBITDA | B16: EBITDA | C16: 1 | D16: =SUMPRODUCT(D2:D15,C2:C15) | E16: =SUMPRODUCT(E2:E14,C2:C14) | F16: =D16-E16 | G16: =IF(E16=0,"",F16/E16)

Sheet Commentary
A1: line_code | B1: line_name | C1: variance (fav +) | D1: explanation | E1: repeats next month? | F1: source
A2: MAT_TIMBER | B2: Timber & panels | C2: -11600 | D2: Brightwood Timber price list +8% on veneer panels from 1 February 2026 (letter of 28 January). About EUR 12k per month at normal volume. Niamh is negotiating a volume rebate. | E2: Yes, every month until a rebate or a new supplier | F2: Email E01 (Brightwood, 28 Jan) and E02 (Niamh, 29 Jan); GL account 5000, invoices BW-INV-10588/10631/10690
